<!-- most of the code is based on: differentialdrive.xml in  https://pab47.github.io/mujocopy.html -->
<mujoco model="wheel">
    <compiler inertiafromgeom="true" angle="degree" coordinate="local"/>
    <option timestep="0.01" integrator="RK4"/>
    <option gravity="0 0 -9.81"/>
    <visual>
        <global offwidth="480" offheight="480"/>
    </visual>
    <asset>
        <texture type="skybox" builtin="gradient" width="100" height="100" rgb1="1 1 1" rgb2="0 0 0"/>
        <texture name="texgeom" type="cube" builtin="flat" mark="cross" width="127" height="1278" rgb1="0.8 0.6 0.4" rgb2="0.8 0.6 0.4" markrgb="1 1 1" random="0.01"/>
        <texture name="texplane" type="2d" builtin="checker" rgb1="1 1 1" rgb2="1 1 1" width="100" height="100"/>
        <material name='MatPlane' texture="texplane" shininess="1" texrepeat="60 60" specular="1" reflectance="0.0"/>
        <material name='geom' texture="texgeom" texuniform="true"/>
    </asset>
    <worldbody>
        <light directional="true" cutoff="100" exponent="1" diffuse="1 1 1" specular=".1 .1 .1" pos="0 0 1.3" dir="-0 0 -1.3"/>
        <geom name='floor' material="MatPlane" pos='0 0 0' size='50 50 50' type='plane' conaffinity='1' rgba='0.8 0.9 0.8 1' condim='3'/>
        <body name="torso" pos="0 0 0.5" euler='0 0 0'>
            <joint name="root" type="free"/>
            <site name="camera_pos" rgba="1 0 0 1" pos="0 0 0.6" size="0.05"/>
            <camera euler="90 -90 0" fovy="120" name="rgb" pos="0 0 0.6"/>
            <geom name="torso_geom" type="cylinder" size=".5 .25" rgba=".9 .9 0 1"/>
            <geom type="sphere" pos="-0.45 0 -0.25" size="0.1" rgba="0 .9 0 1"/>
            <body name="left-tire" pos="0.1 0.5 -0.1" euler='90 0 0'>
                <joint name="left-wheel" type="hinge" axis="0 0 -1"/>
                <geom type="cylinder" size=".25 0.05" rgba="0 .9 0 1"/>
            </body>
            <body name="right-tire" pos="0.1 -0.5 -0.1" euler='90 0 0'>
                <joint name="right-wheel" type="hinge" axis="0 0 -1"/>
                <geom type="cylinder" size=".25 0.05" rgba="0 .9 0 1"/>
            </body>
        </body>
    </worldbody>
    <actuator>
        <velocity ctrllimited="true" name="left-velocity-servo" joint="left-wheel" ctrlrange="-10.0 10.0" kv="100"/>
        <velocity ctrllimited="true" name="right-velocity-servo" joint="right-wheel" ctrlrange="-10.0 10.0" kv="100"/>
    </actuator>
</mujoco>
